2025-05-05 06:47:17,948 INFO    MainThread:50994 [wandb_setup.py:_flush():68] Current SDK version is 0.19.10
2025-05-05 06:47:17,948 INFO    MainThread:50994 [wandb_setup.py:_flush():68] Configure stats pid to 50994
2025-05-05 06:47:17,948 INFO    MainThread:50994 [wandb_setup.py:_flush():68] Loading settings from /root/.config/wandb/settings
2025-05-05 06:47:17,949 INFO    MainThread:50994 [wandb_setup.py:_flush():68] Loading settings from /workspaces/monte-carlo-manipulation/src/wandb/settings
2025-05-05 06:47:17,949 INFO    MainThread:50994 [wandb_setup.py:_flush():68] Loading settings from environment variables
2025-05-05 06:47:17,949 INFO    MainThread:50994 [wandb_init.py:setup_run_log_directory():724] Logging user logs to /workspaces/monte-carlo-manipulation/src/wandb/run-20250505_064717-r98s1wuz/logs/debug.log
2025-05-05 06:47:17,950 INFO    MainThread:50994 [wandb_init.py:setup_run_log_directory():725] Logging internal logs to /workspaces/monte-carlo-manipulation/src/wandb/run-20250505_064717-r98s1wuz/logs/debug-internal.log
2025-05-05 06:47:17,950 INFO    MainThread:50994 [wandb_init.py:init():852] calling init triggers
2025-05-05 06:47:17,950 INFO    MainThread:50994 [wandb_init.py:init():857] wandb.init called with sweep_config: {}
config: {'episodes': 2, 'max_steps': 10, 'budget': 10000, 'update_fq': 5, 'use_wandb': True, 'verbose': True, '_wandb': {}}
2025-05-05 06:47:17,950 INFO    MainThread:50994 [wandb_init.py:init():893] starting backend
2025-05-05 06:47:17,951 INFO    MainThread:50994 [wandb_init.py:init():897] sending inform_init request
2025-05-05 06:47:17,958 INFO    MainThread:50994 [backend.py:_multiprocessing_setup():101] multiprocessing start_methods=fork,spawn,forkserver, using: spawn
2025-05-05 06:47:17,958 INFO    MainThread:50994 [wandb_init.py:init():907] backend started and connected
2025-05-05 06:47:17,960 INFO    MainThread:50994 [wandb_init.py:init():1002] updated telemetry
2025-05-05 06:47:18,091 INFO    MainThread:50994 [wandb_init.py:init():1026] communicating run to backend with 90.0 second timeout
2025-05-05 06:47:18,656 INFO    MainThread:50994 [wandb_init.py:init():1101] starting run threads in backend
2025-05-05 06:47:18,855 INFO    MainThread:50994 [wandb_run.py:_console_start():2566] atexit reg
2025-05-05 06:47:18,855 INFO    MainThread:50994 [wandb_run.py:_redirect():2414] redirect: wrap_raw
2025-05-05 06:47:18,856 INFO    MainThread:50994 [wandb_run.py:_redirect():2483] Wrapping output streams.
2025-05-05 06:47:18,856 INFO    MainThread:50994 [wandb_run.py:_redirect():2506] Redirects installed.
2025-05-05 06:47:18,858 INFO    MainThread:50994 [wandb_init.py:init():1147] run started, returning control to user process
2025-05-05 10:12:10,226 INFO    MsgRouterThr:50994 [mailbox.py:close():129] [no run ID] Closing mailbox, abandoning 1 handles.
2025-05-05 10:12:10,981 ERROR   MainThread:50994 [redirect.py:_on_write():664] [no run ID] error in stderr callback
Traceback (most recent call last):
  File "/usr/local/lib/python3.10/dist-packages/wandb/sdk/lib/redirect.py", line 662, in _on_write
    cb(written_data)
  File "/usr/local/lib/python3.10/dist-packages/wandb/sdk/wandb_run.py", line 2493, in <lambda>
    lambda data: self._console_raw_callback("stderr", data),
  File "/usr/local/lib/python3.10/dist-packages/wandb/sdk/wandb_run.py", line 406, in wrapper
    return func(self, *args, **kwargs)
  File "/usr/local/lib/python3.10/dist-packages/wandb/sdk/wandb_run.py", line 464, in wrapper_fn
    return func(self, *args, **kwargs)
  File "/usr/local/lib/python3.10/dist-packages/wandb/sdk/wandb_run.py", line 1632, in _console_raw_callback
    self._backend.interface.publish_output_raw(name, data)
  File "/usr/local/lib/python3.10/dist-packages/wandb/sdk/interface/interface.py", line 763, in publish_output_raw
    self._publish_output_raw(o)
  File "/usr/local/lib/python3.10/dist-packages/wandb/sdk/interface/interface_shared.py", line 38, in _publish_output_raw
    self._publish(rec)
  File "/usr/local/lib/python3.10/dist-packages/wandb/sdk/interface/interface_sock.py", line 39, in _publish
    self._sock_client.send_record_publish(record)
  File "/usr/local/lib/python3.10/dist-packages/wandb/sdk/lib/sock_client.py", line 174, in send_record_publish
    self.send_server_request(server_req)
  File "/usr/local/lib/python3.10/dist-packages/wandb/sdk/lib/sock_client.py", line 154, in send_server_request
    self._send_message(msg)
  File "/usr/local/lib/python3.10/dist-packages/wandb/sdk/lib/sock_client.py", line 151, in _send_message
    self._sendall_with_error_handle(header + data)
  File "/usr/local/lib/python3.10/dist-packages/wandb/sdk/lib/sock_client.py", line 130, in _sendall_with_error_handle
    sent = self._sock.send(data)
BrokenPipeError: [Errno 32] Broken pipe
2025-05-05 10:12:10,988 ERROR   MainThread:50994 [redirect.py:_on_write():664] [no run ID] error in stderr callback
Traceback (most recent call last):
  File "/usr/local/lib/python3.10/dist-packages/wandb/sdk/lib/redirect.py", line 662, in _on_write
    cb(written_data)
  File "/usr/local/lib/python3.10/dist-packages/wandb/sdk/wandb_run.py", line 2493, in <lambda>
    lambda data: self._console_raw_callback("stderr", data),
  File "/usr/local/lib/python3.10/dist-packages/wandb/sdk/wandb_run.py", line 406, in wrapper
    return func(self, *args, **kwargs)
  File "/usr/local/lib/python3.10/dist-packages/wandb/sdk/wandb_run.py", line 464, in wrapper_fn
    return func(self, *args, **kwargs)
  File "/usr/local/lib/python3.10/dist-packages/wandb/sdk/wandb_run.py", line 1632, in _console_raw_callback
    self._backend.interface.publish_output_raw(name, data)
  File "/usr/local/lib/python3.10/dist-packages/wandb/sdk/interface/interface.py", line 763, in publish_output_raw
    self._publish_output_raw(o)
  File "/usr/local/lib/python3.10/dist-packages/wandb/sdk/interface/interface_shared.py", line 38, in _publish_output_raw
    self._publish(rec)
  File "/usr/local/lib/python3.10/dist-packages/wandb/sdk/interface/interface_sock.py", line 39, in _publish
    self._sock_client.send_record_publish(record)
  File "/usr/local/lib/python3.10/dist-packages/wandb/sdk/lib/sock_client.py", line 174, in send_record_publish
    self.send_server_request(server_req)
  File "/usr/local/lib/python3.10/dist-packages/wandb/sdk/lib/sock_client.py", line 154, in send_server_request
    self._send_message(msg)
  File "/usr/local/lib/python3.10/dist-packages/wandb/sdk/lib/sock_client.py", line 151, in _send_message
    self._sendall_with_error_handle(header + data)
  File "/usr/local/lib/python3.10/dist-packages/wandb/sdk/lib/sock_client.py", line 130, in _sendall_with_error_handle
    sent = self._sock.send(data)
BrokenPipeError: [Errno 32] Broken pipe
2025-05-05 10:12:10,989 ERROR   MainThread:50994 [redirect.py:_on_write():664] [no run ID] error in stderr callback
Traceback (most recent call last):
  File "/usr/local/lib/python3.10/dist-packages/wandb/sdk/lib/redirect.py", line 662, in _on_write
    cb(written_data)
  File "/usr/local/lib/python3.10/dist-packages/wandb/sdk/wandb_run.py", line 2493, in <lambda>
    lambda data: self._console_raw_callback("stderr", data),
  File "/usr/local/lib/python3.10/dist-packages/wandb/sdk/wandb_run.py", line 406, in wrapper
    return func(self, *args, **kwargs)
  File "/usr/local/lib/python3.10/dist-packages/wandb/sdk/wandb_run.py", line 464, in wrapper_fn
    return func(self, *args, **kwargs)
  File "/usr/local/lib/python3.10/dist-packages/wandb/sdk/wandb_run.py", line 1632, in _console_raw_callback
    self._backend.interface.publish_output_raw(name, data)
  File "/usr/local/lib/python3.10/dist-packages/wandb/sdk/interface/interface.py", line 763, in publish_output_raw
    self._publish_output_raw(o)
  File "/usr/local/lib/python3.10/dist-packages/wandb/sdk/interface/interface_shared.py", line 38, in _publish_output_raw
    self._publish(rec)
  File "/usr/local/lib/python3.10/dist-packages/wandb/sdk/interface/interface_sock.py", line 39, in _publish
    self._sock_client.send_record_publish(record)
  File "/usr/local/lib/python3.10/dist-packages/wandb/sdk/lib/sock_client.py", line 174, in send_record_publish
    self.send_server_request(server_req)
  File "/usr/local/lib/python3.10/dist-packages/wandb/sdk/lib/sock_client.py", line 154, in send_server_request
    self._send_message(msg)
  File "/usr/local/lib/python3.10/dist-packages/wandb/sdk/lib/sock_client.py", line 151, in _send_message
    self._sendall_with_error_handle(header + data)
  File "/usr/local/lib/python3.10/dist-packages/wandb/sdk/lib/sock_client.py", line 130, in _sendall_with_error_handle
    sent = self._sock.send(data)
BrokenPipeError: [Errno 32] Broken pipe
2025-05-05 10:12:10,990 ERROR   MainThread:50994 [redirect.py:_on_write():664] [no run ID] error in stderr callback
Traceback (most recent call last):
  File "/usr/local/lib/python3.10/dist-packages/wandb/sdk/lib/redirect.py", line 662, in _on_write
    cb(written_data)
  File "/usr/local/lib/python3.10/dist-packages/wandb/sdk/wandb_run.py", line 2493, in <lambda>
    lambda data: self._console_raw_callback("stderr", data),
  File "/usr/local/lib/python3.10/dist-packages/wandb/sdk/wandb_run.py", line 406, in wrapper
    return func(self, *args, **kwargs)
  File "/usr/local/lib/python3.10/dist-packages/wandb/sdk/wandb_run.py", line 464, in wrapper_fn
    return func(self, *args, **kwargs)
  File "/usr/local/lib/python3.10/dist-packages/wandb/sdk/wandb_run.py", line 1632, in _console_raw_callback
    self._backend.interface.publish_output_raw(name, data)
  File "/usr/local/lib/python3.10/dist-packages/wandb/sdk/interface/interface.py", line 763, in publish_output_raw
    self._publish_output_raw(o)
  File "/usr/local/lib/python3.10/dist-packages/wandb/sdk/interface/interface_shared.py", line 38, in _publish_output_raw
    self._publish(rec)
  File "/usr/local/lib/python3.10/dist-packages/wandb/sdk/interface/interface_sock.py", line 39, in _publish
    self._sock_client.send_record_publish(record)
  File "/usr/local/lib/python3.10/dist-packages/wandb/sdk/lib/sock_client.py", line 174, in send_record_publish
    self.send_server_request(server_req)
  File "/usr/local/lib/python3.10/dist-packages/wandb/sdk/lib/sock_client.py", line 154, in send_server_request
    self._send_message(msg)
  File "/usr/local/lib/python3.10/dist-packages/wandb/sdk/lib/sock_client.py", line 151, in _send_message
    self._sendall_with_error_handle(header + data)
  File "/usr/local/lib/python3.10/dist-packages/wandb/sdk/lib/sock_client.py", line 130, in _sendall_with_error_handle
    sent = self._sock.send(data)
BrokenPipeError: [Errno 32] Broken pipe
2025-05-05 10:12:10,991 ERROR   MainThread:50994 [redirect.py:_on_write():664] [no run ID] error in stderr callback
Traceback (most recent call last):
  File "/usr/local/lib/python3.10/dist-packages/wandb/sdk/lib/redirect.py", line 662, in _on_write
    cb(written_data)
  File "/usr/local/lib/python3.10/dist-packages/wandb/sdk/wandb_run.py", line 2493, in <lambda>
    lambda data: self._console_raw_callback("stderr", data),
  File "/usr/local/lib/python3.10/dist-packages/wandb/sdk/wandb_run.py", line 406, in wrapper
    return func(self, *args, **kwargs)
  File "/usr/local/lib/python3.10/dist-packages/wandb/sdk/wandb_run.py", line 464, in wrapper_fn
    return func(self, *args, **kwargs)
  File "/usr/local/lib/python3.10/dist-packages/wandb/sdk/wandb_run.py", line 1632, in _console_raw_callback
    self._backend.interface.publish_output_raw(name, data)
  File "/usr/local/lib/python3.10/dist-packages/wandb/sdk/interface/interface.py", line 763, in publish_output_raw
    self._publish_output_raw(o)
  File "/usr/local/lib/python3.10/dist-packages/wandb/sdk/interface/interface_shared.py", line 38, in _publish_output_raw
    self._publish(rec)
  File "/usr/local/lib/python3.10/dist-packages/wandb/sdk/interface/interface_sock.py", line 39, in _publish
    self._sock_client.send_record_publish(record)
  File "/usr/local/lib/python3.10/dist-packages/wandb/sdk/lib/sock_client.py", line 174, in send_record_publish
    self.send_server_request(server_req)
  File "/usr/local/lib/python3.10/dist-packages/wandb/sdk/lib/sock_client.py", line 154, in send_server_request
    self._send_message(msg)
  File "/usr/local/lib/python3.10/dist-packages/wandb/sdk/lib/sock_client.py", line 151, in _send_message
    self._sendall_with_error_handle(header + data)
  File "/usr/local/lib/python3.10/dist-packages/wandb/sdk/lib/sock_client.py", line 130, in _sendall_with_error_handle
    sent = self._sock.send(data)
BrokenPipeError: [Errno 32] Broken pipe
2025-05-05 10:12:10,992 ERROR   MainThread:50994 [redirect.py:_on_write():664] [no run ID] error in stderr callback
Traceback (most recent call last):
  File "/usr/local/lib/python3.10/dist-packages/wandb/sdk/lib/redirect.py", line 662, in _on_write
    cb(written_data)
  File "/usr/local/lib/python3.10/dist-packages/wandb/sdk/wandb_run.py", line 2493, in <lambda>
    lambda data: self._console_raw_callback("stderr", data),
  File "/usr/local/lib/python3.10/dist-packages/wandb/sdk/wandb_run.py", line 406, in wrapper
    return func(self, *args, **kwargs)
  File "/usr/local/lib/python3.10/dist-packages/wandb/sdk/wandb_run.py", line 464, in wrapper_fn
    return func(self, *args, **kwargs)
  File "/usr/local/lib/python3.10/dist-packages/wandb/sdk/wandb_run.py", line 1632, in _console_raw_callback
    self._backend.interface.publish_output_raw(name, data)
  File "/usr/local/lib/python3.10/dist-packages/wandb/sdk/interface/interface.py", line 763, in publish_output_raw
    self._publish_output_raw(o)
  File "/usr/local/lib/python3.10/dist-packages/wandb/sdk/interface/interface_shared.py", line 38, in _publish_output_raw
    self._publish(rec)
  File "/usr/local/lib/python3.10/dist-packages/wandb/sdk/interface/interface_sock.py", line 39, in _publish
    self._sock_client.send_record_publish(record)
  File "/usr/local/lib/python3.10/dist-packages/wandb/sdk/lib/sock_client.py", line 174, in send_record_publish
    self.send_server_request(server_req)
  File "/usr/local/lib/python3.10/dist-packages/wandb/sdk/lib/sock_client.py", line 154, in send_server_request
    self._send_message(msg)
  File "/usr/local/lib/python3.10/dist-packages/wandb/sdk/lib/sock_client.py", line 151, in _send_message
    self._sendall_with_error_handle(header + data)
  File "/usr/local/lib/python3.10/dist-packages/wandb/sdk/lib/sock_client.py", line 130, in _sendall_with_error_handle
    sent = self._sock.send(data)
BrokenPipeError: [Errno 32] Broken pipe
2025-05-05 10:12:10,993 ERROR   MainThread:50994 [redirect.py:_on_write():664] [no run ID] error in stderr callback
Traceback (most recent call last):
  File "/usr/local/lib/python3.10/dist-packages/wandb/sdk/lib/redirect.py", line 662, in _on_write
    cb(written_data)
  File "/usr/local/lib/python3.10/dist-packages/wandb/sdk/wandb_run.py", line 2493, in <lambda>
    lambda data: self._console_raw_callback("stderr", data),
  File "/usr/local/lib/python3.10/dist-packages/wandb/sdk/wandb_run.py", line 406, in wrapper
    return func(self, *args, **kwargs)
  File "/usr/local/lib/python3.10/dist-packages/wandb/sdk/wandb_run.py", line 464, in wrapper_fn
    return func(self, *args, **kwargs)
  File "/usr/local/lib/python3.10/dist-packages/wandb/sdk/wandb_run.py", line 1632, in _console_raw_callback
    self._backend.interface.publish_output_raw(name, data)
  File "/usr/local/lib/python3.10/dist-packages/wandb/sdk/interface/interface.py", line 763, in publish_output_raw
    self._publish_output_raw(o)
  File "/usr/local/lib/python3.10/dist-packages/wandb/sdk/interface/interface_shared.py", line 38, in _publish_output_raw
    self._publish(rec)
  File "/usr/local/lib/python3.10/dist-packages/wandb/sdk/interface/interface_sock.py", line 39, in _publish
    self._sock_client.send_record_publish(record)
  File "/usr/local/lib/python3.10/dist-packages/wandb/sdk/lib/sock_client.py", line 174, in send_record_publish
    self.send_server_request(server_req)
  File "/usr/local/lib/python3.10/dist-packages/wandb/sdk/lib/sock_client.py", line 154, in send_server_request
    self._send_message(msg)
  File "/usr/local/lib/python3.10/dist-packages/wandb/sdk/lib/sock_client.py", line 151, in _send_message
    self._sendall_with_error_handle(header + data)
  File "/usr/local/lib/python3.10/dist-packages/wandb/sdk/lib/sock_client.py", line 130, in _sendall_with_error_handle
    sent = self._sock.send(data)
BrokenPipeError: [Errno 32] Broken pipe
2025-05-05 10:12:10,993 ERROR   MainThread:50994 [redirect.py:_on_write():664] [no run ID] error in stderr callback
Traceback (most recent call last):
  File "/usr/local/lib/python3.10/dist-packages/wandb/sdk/lib/redirect.py", line 662, in _on_write
    cb(written_data)
  File "/usr/local/lib/python3.10/dist-packages/wandb/sdk/wandb_run.py", line 2493, in <lambda>
    lambda data: self._console_raw_callback("stderr", data),
  File "/usr/local/lib/python3.10/dist-packages/wandb/sdk/wandb_run.py", line 406, in wrapper
    return func(self, *args, **kwargs)
  File "/usr/local/lib/python3.10/dist-packages/wandb/sdk/wandb_run.py", line 464, in wrapper_fn
    return func(self, *args, **kwargs)
  File "/usr/local/lib/python3.10/dist-packages/wandb/sdk/wandb_run.py", line 1632, in _console_raw_callback
    self._backend.interface.publish_output_raw(name, data)
  File "/usr/local/lib/python3.10/dist-packages/wandb/sdk/interface/interface.py", line 763, in publish_output_raw
    self._publish_output_raw(o)
  File "/usr/local/lib/python3.10/dist-packages/wandb/sdk/interface/interface_shared.py", line 38, in _publish_output_raw
    self._publish(rec)
  File "/usr/local/lib/python3.10/dist-packages/wandb/sdk/interface/interface_sock.py", line 39, in _publish
    self._sock_client.send_record_publish(record)
  File "/usr/local/lib/python3.10/dist-packages/wandb/sdk/lib/sock_client.py", line 174, in send_record_publish
    self.send_server_request(server_req)
  File "/usr/local/lib/python3.10/dist-packages/wandb/sdk/lib/sock_client.py", line 154, in send_server_request
    self._send_message(msg)
  File "/usr/local/lib/python3.10/dist-packages/wandb/sdk/lib/sock_client.py", line 151, in _send_message
    self._sendall_with_error_handle(header + data)
  File "/usr/local/lib/python3.10/dist-packages/wandb/sdk/lib/sock_client.py", line 130, in _sendall_with_error_handle
    sent = self._sock.send(data)
BrokenPipeError: [Errno 32] Broken pipe
2025-05-05 10:12:10,994 ERROR   MainThread:50994 [redirect.py:_on_write():664] [no run ID] error in stderr callback
Traceback (most recent call last):
  File "/usr/local/lib/python3.10/dist-packages/wandb/sdk/lib/redirect.py", line 662, in _on_write
    cb(written_data)
  File "/usr/local/lib/python3.10/dist-packages/wandb/sdk/wandb_run.py", line 2493, in <lambda>
    lambda data: self._console_raw_callback("stderr", data),
  File "/usr/local/lib/python3.10/dist-packages/wandb/sdk/wandb_run.py", line 406, in wrapper
    return func(self, *args, **kwargs)
  File "/usr/local/lib/python3.10/dist-packages/wandb/sdk/wandb_run.py", line 464, in wrapper_fn
    return func(self, *args, **kwargs)
  File "/usr/local/lib/python3.10/dist-packages/wandb/sdk/wandb_run.py", line 1632, in _console_raw_callback
    self._backend.interface.publish_output_raw(name, data)
  File "/usr/local/lib/python3.10/dist-packages/wandb/sdk/interface/interface.py", line 763, in publish_output_raw
    self._publish_output_raw(o)
  File "/usr/local/lib/python3.10/dist-packages/wandb/sdk/interface/interface_shared.py", line 38, in _publish_output_raw
    self._publish(rec)
  File "/usr/local/lib/python3.10/dist-packages/wandb/sdk/interface/interface_sock.py", line 39, in _publish
    self._sock_client.send_record_publish(record)
  File "/usr/local/lib/python3.10/dist-packages/wandb/sdk/lib/sock_client.py", line 174, in send_record_publish
    self.send_server_request(server_req)
  File "/usr/local/lib/python3.10/dist-packages/wandb/sdk/lib/sock_client.py", line 154, in send_server_request
    self._send_message(msg)
  File "/usr/local/lib/python3.10/dist-packages/wandb/sdk/lib/sock_client.py", line 151, in _send_message
    self._sendall_with_error_handle(header + data)
  File "/usr/local/lib/python3.10/dist-packages/wandb/sdk/lib/sock_client.py", line 130, in _sendall_with_error_handle
    sent = self._sock.send(data)
BrokenPipeError: [Errno 32] Broken pipe
2025-05-05 10:12:10,994 ERROR   MainThread:50994 [redirect.py:_on_write():664] [no run ID] error in stderr callback
Traceback (most recent call last):
  File "/usr/local/lib/python3.10/dist-packages/wandb/sdk/lib/redirect.py", line 662, in _on_write
    cb(written_data)
  File "/usr/local/lib/python3.10/dist-packages/wandb/sdk/wandb_run.py", line 2493, in <lambda>
    lambda data: self._console_raw_callback("stderr", data),
  File "/usr/local/lib/python3.10/dist-packages/wandb/sdk/wandb_run.py", line 406, in wrapper
    return func(self, *args, **kwargs)
  File "/usr/local/lib/python3.10/dist-packages/wandb/sdk/wandb_run.py", line 464, in wrapper_fn
    return func(self, *args, **kwargs)
  File "/usr/local/lib/python3.10/dist-packages/wandb/sdk/wandb_run.py", line 1632, in _console_raw_callback
    self._backend.interface.publish_output_raw(name, data)
  File "/usr/local/lib/python3.10/dist-packages/wandb/sdk/interface/interface.py", line 763, in publish_output_raw
    self._publish_output_raw(o)
  File "/usr/local/lib/python3.10/dist-packages/wandb/sdk/interface/interface_shared.py", line 38, in _publish_output_raw
    self._publish(rec)
  File "/usr/local/lib/python3.10/dist-packages/wandb/sdk/interface/interface_sock.py", line 39, in _publish
    self._sock_client.send_record_publish(record)
  File "/usr/local/lib/python3.10/dist-packages/wandb/sdk/lib/sock_client.py", line 174, in send_record_publish
    self.send_server_request(server_req)
  File "/usr/local/lib/python3.10/dist-packages/wandb/sdk/lib/sock_client.py", line 154, in send_server_request
    self._send_message(msg)
  File "/usr/local/lib/python3.10/dist-packages/wandb/sdk/lib/sock_client.py", line 151, in _send_message
    self._sendall_with_error_handle(header + data)
  File "/usr/local/lib/python3.10/dist-packages/wandb/sdk/lib/sock_client.py", line 130, in _sendall_with_error_handle
    sent = self._sock.send(data)
BrokenPipeError: [Errno 32] Broken pipe
2025-05-05 10:12:10,996 ERROR   MainThread:50994 [redirect.py:_on_write():664] [no run ID] error in stderr callback
Traceback (most recent call last):
  File "/usr/local/lib/python3.10/dist-packages/wandb/sdk/lib/redirect.py", line 662, in _on_write
    cb(written_data)
  File "/usr/local/lib/python3.10/dist-packages/wandb/sdk/wandb_run.py", line 2493, in <lambda>
    lambda data: self._console_raw_callback("stderr", data),
  File "/usr/local/lib/python3.10/dist-packages/wandb/sdk/wandb_run.py", line 406, in wrapper
    return func(self, *args, **kwargs)
  File "/usr/local/lib/python3.10/dist-packages/wandb/sdk/wandb_run.py", line 464, in wrapper_fn
    return func(self, *args, **kwargs)
  File "/usr/local/lib/python3.10/dist-packages/wandb/sdk/wandb_run.py", line 1632, in _console_raw_callback
    self._backend.interface.publish_output_raw(name, data)
  File "/usr/local/lib/python3.10/dist-packages/wandb/sdk/interface/interface.py", line 763, in publish_output_raw
    self._publish_output_raw(o)
  File "/usr/local/lib/python3.10/dist-packages/wandb/sdk/interface/interface_shared.py", line 38, in _publish_output_raw
    self._publish(rec)
  File "/usr/local/lib/python3.10/dist-packages/wandb/sdk/interface/interface_sock.py", line 39, in _publish
    self._sock_client.send_record_publish(record)
  File "/usr/local/lib/python3.10/dist-packages/wandb/sdk/lib/sock_client.py", line 174, in send_record_publish
    self.send_server_request(server_req)
  File "/usr/local/lib/python3.10/dist-packages/wandb/sdk/lib/sock_client.py", line 154, in send_server_request
    self._send_message(msg)
  File "/usr/local/lib/python3.10/dist-packages/wandb/sdk/lib/sock_client.py", line 151, in _send_message
    self._sendall_with_error_handle(header + data)
  File "/usr/local/lib/python3.10/dist-packages/wandb/sdk/lib/sock_client.py", line 130, in _sendall_with_error_handle
    sent = self._sock.send(data)
BrokenPipeError: [Errno 32] Broken pipe
2025-05-05 10:12:10,997 ERROR   MainThread:50994 [redirect.py:_on_write():664] [no run ID] error in stderr callback
Traceback (most recent call last):
  File "/usr/local/lib/python3.10/dist-packages/wandb/sdk/lib/redirect.py", line 662, in _on_write
    cb(written_data)
  File "/usr/local/lib/python3.10/dist-packages/wandb/sdk/wandb_run.py", line 2493, in <lambda>
    lambda data: self._console_raw_callback("stderr", data),
  File "/usr/local/lib/python3.10/dist-packages/wandb/sdk/wandb_run.py", line 406, in wrapper
    return func(self, *args, **kwargs)
  File "/usr/local/lib/python3.10/dist-packages/wandb/sdk/wandb_run.py", line 464, in wrapper_fn
    return func(self, *args, **kwargs)
  File "/usr/local/lib/python3.10/dist-packages/wandb/sdk/wandb_run.py", line 1632, in _console_raw_callback
    self._backend.interface.publish_output_raw(name, data)
  File "/usr/local/lib/python3.10/dist-packages/wandb/sdk/interface/interface.py", line 763, in publish_output_raw
    self._publish_output_raw(o)
  File "/usr/local/lib/python3.10/dist-packages/wandb/sdk/interface/interface_shared.py", line 38, in _publish_output_raw
    self._publish(rec)
  File "/usr/local/lib/python3.10/dist-packages/wandb/sdk/interface/interface_sock.py", line 39, in _publish
    self._sock_client.send_record_publish(record)
  File "/usr/local/lib/python3.10/dist-packages/wandb/sdk/lib/sock_client.py", line 174, in send_record_publish
    self.send_server_request(server_req)
  File "/usr/local/lib/python3.10/dist-packages/wandb/sdk/lib/sock_client.py", line 154, in send_server_request
    self._send_message(msg)
  File "/usr/local/lib/python3.10/dist-packages/wandb/sdk/lib/sock_client.py", line 151, in _send_message
    self._sendall_with_error_handle(header + data)
  File "/usr/local/lib/python3.10/dist-packages/wandb/sdk/lib/sock_client.py", line 130, in _sendall_with_error_handle
    sent = self._sock.send(data)
BrokenPipeError: [Errno 32] Broken pipe
2025-05-05 10:12:10,998 ERROR   MainThread:50994 [redirect.py:_on_write():664] [no run ID] error in stderr callback
Traceback (most recent call last):
  File "/usr/local/lib/python3.10/dist-packages/wandb/sdk/lib/redirect.py", line 662, in _on_write
    cb(written_data)
  File "/usr/local/lib/python3.10/dist-packages/wandb/sdk/wandb_run.py", line 2493, in <lambda>
    lambda data: self._console_raw_callback("stderr", data),
  File "/usr/local/lib/python3.10/dist-packages/wandb/sdk/wandb_run.py", line 406, in wrapper
    return func(self, *args, **kwargs)
  File "/usr/local/lib/python3.10/dist-packages/wandb/sdk/wandb_run.py", line 464, in wrapper_fn
    return func(self, *args, **kwargs)
  File "/usr/local/lib/python3.10/dist-packages/wandb/sdk/wandb_run.py", line 1632, in _console_raw_callback
    self._backend.interface.publish_output_raw(name, data)
  File "/usr/local/lib/python3.10/dist-packages/wandb/sdk/interface/interface.py", line 763, in publish_output_raw
    self._publish_output_raw(o)
  File "/usr/local/lib/python3.10/dist-packages/wandb/sdk/interface/interface_shared.py", line 38, in _publish_output_raw
    self._publish(rec)
  File "/usr/local/lib/python3.10/dist-packages/wandb/sdk/interface/interface_sock.py", line 39, in _publish
    self._sock_client.send_record_publish(record)
  File "/usr/local/lib/python3.10/dist-packages/wandb/sdk/lib/sock_client.py", line 174, in send_record_publish
    self.send_server_request(server_req)
  File "/usr/local/lib/python3.10/dist-packages/wandb/sdk/lib/sock_client.py", line 154, in send_server_request
    self._send_message(msg)
  File "/usr/local/lib/python3.10/dist-packages/wandb/sdk/lib/sock_client.py", line 151, in _send_message
    self._sendall_with_error_handle(header + data)
  File "/usr/local/lib/python3.10/dist-packages/wandb/sdk/lib/sock_client.py", line 130, in _sendall_with_error_handle
    sent = self._sock.send(data)
BrokenPipeError: [Errno 32] Broken pipe
2025-05-05 10:12:10,998 ERROR   MainThread:50994 [redirect.py:_on_write():664] [no run ID] error in stderr callback
Traceback (most recent call last):
  File "/usr/local/lib/python3.10/dist-packages/wandb/sdk/lib/redirect.py", line 662, in _on_write
    cb(written_data)
  File "/usr/local/lib/python3.10/dist-packages/wandb/sdk/wandb_run.py", line 2493, in <lambda>
    lambda data: self._console_raw_callback("stderr", data),
  File "/usr/local/lib/python3.10/dist-packages/wandb/sdk/wandb_run.py", line 406, in wrapper
    return func(self, *args, **kwargs)
  File "/usr/local/lib/python3.10/dist-packages/wandb/sdk/wandb_run.py", line 464, in wrapper_fn
    return func(self, *args, **kwargs)
  File "/usr/local/lib/python3.10/dist-packages/wandb/sdk/wandb_run.py", line 1632, in _console_raw_callback
    self._backend.interface.publish_output_raw(name, data)
  File "/usr/local/lib/python3.10/dist-packages/wandb/sdk/interface/interface.py", line 763, in publish_output_raw
    self._publish_output_raw(o)
  File "/usr/local/lib/python3.10/dist-packages/wandb/sdk/interface/interface_shared.py", line 38, in _publish_output_raw
    self._publish(rec)
  File "/usr/local/lib/python3.10/dist-packages/wandb/sdk/interface/interface_sock.py", line 39, in _publish
    self._sock_client.send_record_publish(record)
  File "/usr/local/lib/python3.10/dist-packages/wandb/sdk/lib/sock_client.py", line 174, in send_record_publish
    self.send_server_request(server_req)
  File "/usr/local/lib/python3.10/dist-packages/wandb/sdk/lib/sock_client.py", line 154, in send_server_request
    self._send_message(msg)
  File "/usr/local/lib/python3.10/dist-packages/wandb/sdk/lib/sock_client.py", line 151, in _send_message
    self._sendall_with_error_handle(header + data)
  File "/usr/local/lib/python3.10/dist-packages/wandb/sdk/lib/sock_client.py", line 130, in _sendall_with_error_handle
    sent = self._sock.send(data)
BrokenPipeError: [Errno 32] Broken pipe
2025-05-05 10:12:10,999 ERROR   MainThread:50994 [redirect.py:_on_write():664] [no run ID] error in stderr callback
Traceback (most recent call last):
  File "/usr/local/lib/python3.10/dist-packages/wandb/sdk/lib/redirect.py", line 662, in _on_write
    cb(written_data)
  File "/usr/local/lib/python3.10/dist-packages/wandb/sdk/wandb_run.py", line 2493, in <lambda>
    lambda data: self._console_raw_callback("stderr", data),
  File "/usr/local/lib/python3.10/dist-packages/wandb/sdk/wandb_run.py", line 406, in wrapper
    return func(self, *args, **kwargs)
  File "/usr/local/lib/python3.10/dist-packages/wandb/sdk/wandb_run.py", line 464, in wrapper_fn
    return func(self, *args, **kwargs)
  File "/usr/local/lib/python3.10/dist-packages/wandb/sdk/wandb_run.py", line 1632, in _console_raw_callback
    self._backend.interface.publish_output_raw(name, data)
  File "/usr/local/lib/python3.10/dist-packages/wandb/sdk/interface/interface.py", line 763, in publish_output_raw
    self._publish_output_raw(o)
  File "/usr/local/lib/python3.10/dist-packages/wandb/sdk/interface/interface_shared.py", line 38, in _publish_output_raw
    self._publish(rec)
  File "/usr/local/lib/python3.10/dist-packages/wandb/sdk/interface/interface_sock.py", line 39, in _publish
    self._sock_client.send_record_publish(record)
  File "/usr/local/lib/python3.10/dist-packages/wandb/sdk/lib/sock_client.py", line 174, in send_record_publish
    self.send_server_request(server_req)
  File "/usr/local/lib/python3.10/dist-packages/wandb/sdk/lib/sock_client.py", line 154, in send_server_request
    self._send_message(msg)
  File "/usr/local/lib/python3.10/dist-packages/wandb/sdk/lib/sock_client.py", line 151, in _send_message
    self._sendall_with_error_handle(header + data)
  File "/usr/local/lib/python3.10/dist-packages/wandb/sdk/lib/sock_client.py", line 130, in _sendall_with_error_handle
    sent = self._sock.send(data)
BrokenPipeError: [Errno 32] Broken pipe
2025-05-05 10:12:11,000 ERROR   MainThread:50994 [redirect.py:_on_write():664] [no run ID] error in stderr callback
Traceback (most recent call last):
  File "/usr/local/lib/python3.10/dist-packages/wandb/sdk/lib/redirect.py", line 662, in _on_write
    cb(written_data)
  File "/usr/local/lib/python3.10/dist-packages/wandb/sdk/wandb_run.py", line 2493, in <lambda>
    lambda data: self._console_raw_callback("stderr", data),
  File "/usr/local/lib/python3.10/dist-packages/wandb/sdk/wandb_run.py", line 406, in wrapper
    return func(self, *args, **kwargs)
  File "/usr/local/lib/python3.10/dist-packages/wandb/sdk/wandb_run.py", line 464, in wrapper_fn
    return func(self, *args, **kwargs)
  File "/usr/local/lib/python3.10/dist-packages/wandb/sdk/wandb_run.py", line 1632, in _console_raw_callback
    self._backend.interface.publish_output_raw(name, data)
  File "/usr/local/lib/python3.10/dist-packages/wandb/sdk/interface/interface.py", line 763, in publish_output_raw
    self._publish_output_raw(o)
  File "/usr/local/lib/python3.10/dist-packages/wandb/sdk/interface/interface_shared.py", line 38, in _publish_output_raw
    self._publish(rec)
  File "/usr/local/lib/python3.10/dist-packages/wandb/sdk/interface/interface_sock.py", line 39, in _publish
    self._sock_client.send_record_publish(record)
  File "/usr/local/lib/python3.10/dist-packages/wandb/sdk/lib/sock_client.py", line 174, in send_record_publish
    self.send_server_request(server_req)
  File "/usr/local/lib/python3.10/dist-packages/wandb/sdk/lib/sock_client.py", line 154, in send_server_request
    self._send_message(msg)
  File "/usr/local/lib/python3.10/dist-packages/wandb/sdk/lib/sock_client.py", line 151, in _send_message
    self._sendall_with_error_handle(header + data)
  File "/usr/local/lib/python3.10/dist-packages/wandb/sdk/lib/sock_client.py", line 130, in _sendall_with_error_handle
    sent = self._sock.send(data)
BrokenPipeError: [Errno 32] Broken pipe
2025-05-05 10:12:11,000 ERROR   MainThread:50994 [redirect.py:_on_write():664] [no run ID] error in stderr callback
Traceback (most recent call last):
  File "/usr/local/lib/python3.10/dist-packages/wandb/sdk/lib/redirect.py", line 662, in _on_write
    cb(written_data)
  File "/usr/local/lib/python3.10/dist-packages/wandb/sdk/wandb_run.py", line 2493, in <lambda>
    lambda data: self._console_raw_callback("stderr", data),
  File "/usr/local/lib/python3.10/dist-packages/wandb/sdk/wandb_run.py", line 406, in wrapper
    return func(self, *args, **kwargs)
  File "/usr/local/lib/python3.10/dist-packages/wandb/sdk/wandb_run.py", line 464, in wrapper_fn
    return func(self, *args, **kwargs)
  File "/usr/local/lib/python3.10/dist-packages/wandb/sdk/wandb_run.py", line 1632, in _console_raw_callback
    self._backend.interface.publish_output_raw(name, data)
  File "/usr/local/lib/python3.10/dist-packages/wandb/sdk/interface/interface.py", line 763, in publish_output_raw
    self._publish_output_raw(o)
  File "/usr/local/lib/python3.10/dist-packages/wandb/sdk/interface/interface_shared.py", line 38, in _publish_output_raw
    self._publish(rec)
  File "/usr/local/lib/python3.10/dist-packages/wandb/sdk/interface/interface_sock.py", line 39, in _publish
    self._sock_client.send_record_publish(record)
  File "/usr/local/lib/python3.10/dist-packages/wandb/sdk/lib/sock_client.py", line 174, in send_record_publish
    self.send_server_request(server_req)
  File "/usr/local/lib/python3.10/dist-packages/wandb/sdk/lib/sock_client.py", line 154, in send_server_request
    self._send_message(msg)
  File "/usr/local/lib/python3.10/dist-packages/wandb/sdk/lib/sock_client.py", line 151, in _send_message
    self._sendall_with_error_handle(header + data)
  File "/usr/local/lib/python3.10/dist-packages/wandb/sdk/lib/sock_client.py", line 130, in _sendall_with_error_handle
    sent = self._sock.send(data)
BrokenPipeError: [Errno 32] Broken pipe
2025-05-05 10:12:11,004 ERROR   MainThread:50994 [redirect.py:_on_write():664] [no run ID] error in stderr callback
Traceback (most recent call last):
  File "/usr/local/lib/python3.10/dist-packages/wandb/sdk/lib/redirect.py", line 662, in _on_write
    cb(written_data)
  File "/usr/local/lib/python3.10/dist-packages/wandb/sdk/wandb_run.py", line 2493, in <lambda>
    lambda data: self._console_raw_callback("stderr", data),
  File "/usr/local/lib/python3.10/dist-packages/wandb/sdk/wandb_run.py", line 406, in wrapper
    return func(self, *args, **kwargs)
  File "/usr/local/lib/python3.10/dist-packages/wandb/sdk/wandb_run.py", line 464, in wrapper_fn
    return func(self, *args, **kwargs)
  File "/usr/local/lib/python3.10/dist-packages/wandb/sdk/wandb_run.py", line 1632, in _console_raw_callback
    self._backend.interface.publish_output_raw(name, data)
  File "/usr/local/lib/python3.10/dist-packages/wandb/sdk/interface/interface.py", line 763, in publish_output_raw
    self._publish_output_raw(o)
  File "/usr/local/lib/python3.10/dist-packages/wandb/sdk/interface/interface_shared.py", line 38, in _publish_output_raw
    self._publish(rec)
  File "/usr/local/lib/python3.10/dist-packages/wandb/sdk/interface/interface_sock.py", line 39, in _publish
    self._sock_client.send_record_publish(record)
  File "/usr/local/lib/python3.10/dist-packages/wandb/sdk/lib/sock_client.py", line 174, in send_record_publish
    self.send_server_request(server_req)
  File "/usr/local/lib/python3.10/dist-packages/wandb/sdk/lib/sock_client.py", line 154, in send_server_request
    self._send_message(msg)
  File "/usr/local/lib/python3.10/dist-packages/wandb/sdk/lib/sock_client.py", line 151, in _send_message
    self._sendall_with_error_handle(header + data)
  File "/usr/local/lib/python3.10/dist-packages/wandb/sdk/lib/sock_client.py", line 130, in _sendall_with_error_handle
    sent = self._sock.send(data)
BrokenPipeError: [Errno 32] Broken pipe
2025-05-05 10:12:11,005 ERROR   MainThread:50994 [redirect.py:_on_write():664] [no run ID] error in stderr callback
Traceback (most recent call last):
  File "/usr/local/lib/python3.10/dist-packages/wandb/sdk/lib/redirect.py", line 662, in _on_write
    cb(written_data)
  File "/usr/local/lib/python3.10/dist-packages/wandb/sdk/wandb_run.py", line 2493, in <lambda>
    lambda data: self._console_raw_callback("stderr", data),
  File "/usr/local/lib/python3.10/dist-packages/wandb/sdk/wandb_run.py", line 406, in wrapper
    return func(self, *args, **kwargs)
  File "/usr/local/lib/python3.10/dist-packages/wandb/sdk/wandb_run.py", line 464, in wrapper_fn
    return func(self, *args, **kwargs)
  File "/usr/local/lib/python3.10/dist-packages/wandb/sdk/wandb_run.py", line 1632, in _console_raw_callback
    self._backend.interface.publish_output_raw(name, data)
  File "/usr/local/lib/python3.10/dist-packages/wandb/sdk/interface/interface.py", line 763, in publish_output_raw
    self._publish_output_raw(o)
  File "/usr/local/lib/python3.10/dist-packages/wandb/sdk/interface/interface_shared.py", line 38, in _publish_output_raw
    self._publish(rec)
  File "/usr/local/lib/python3.10/dist-packages/wandb/sdk/interface/interface_sock.py", line 39, in _publish
    self._sock_client.send_record_publish(record)
  File "/usr/local/lib/python3.10/dist-packages/wandb/sdk/lib/sock_client.py", line 174, in send_record_publish
    self.send_server_request(server_req)
  File "/usr/local/lib/python3.10/dist-packages/wandb/sdk/lib/sock_client.py", line 154, in send_server_request
    self._send_message(msg)
  File "/usr/local/lib/python3.10/dist-packages/wandb/sdk/lib/sock_client.py", line 151, in _send_message
    self._sendall_with_error_handle(header + data)
  File "/usr/local/lib/python3.10/dist-packages/wandb/sdk/lib/sock_client.py", line 130, in _sendall_with_error_handle
    sent = self._sock.send(data)
BrokenPipeError: [Errno 32] Broken pipe
2025-05-05 10:12:11,005 ERROR   MainThread:50994 [redirect.py:_on_write():664] [no run ID] error in stderr callback
Traceback (most recent call last):
  File "/usr/local/lib/python3.10/dist-packages/wandb/sdk/lib/redirect.py", line 662, in _on_write
    cb(written_data)
  File "/usr/local/lib/python3.10/dist-packages/wandb/sdk/wandb_run.py", line 2493, in <lambda>
    lambda data: self._console_raw_callback("stderr", data),
  File "/usr/local/lib/python3.10/dist-packages/wandb/sdk/wandb_run.py", line 406, in wrapper
    return func(self, *args, **kwargs)
  File "/usr/local/lib/python3.10/dist-packages/wandb/sdk/wandb_run.py", line 464, in wrapper_fn
    return func(self, *args, **kwargs)
  File "/usr/local/lib/python3.10/dist-packages/wandb/sdk/wandb_run.py", line 1632, in _console_raw_callback
    self._backend.interface.publish_output_raw(name, data)
  File "/usr/local/lib/python3.10/dist-packages/wandb/sdk/interface/interface.py", line 763, in publish_output_raw
    self._publish_output_raw(o)
  File "/usr/local/lib/python3.10/dist-packages/wandb/sdk/interface/interface_shared.py", line 38, in _publish_output_raw
    self._publish(rec)
  File "/usr/local/lib/python3.10/dist-packages/wandb/sdk/interface/interface_sock.py", line 39, in _publish
    self._sock_client.send_record_publish(record)
  File "/usr/local/lib/python3.10/dist-packages/wandb/sdk/lib/sock_client.py", line 174, in send_record_publish
    self.send_server_request(server_req)
  File "/usr/local/lib/python3.10/dist-packages/wandb/sdk/lib/sock_client.py", line 154, in send_server_request
    self._send_message(msg)
  File "/usr/local/lib/python3.10/dist-packages/wandb/sdk/lib/sock_client.py", line 151, in _send_message
    self._sendall_with_error_handle(header + data)
  File "/usr/local/lib/python3.10/dist-packages/wandb/sdk/lib/sock_client.py", line 130, in _sendall_with_error_handle
    sent = self._sock.send(data)
BrokenPipeError: [Errno 32] Broken pipe
2025-05-05 10:12:11,006 ERROR   MainThread:50994 [redirect.py:_on_write():664] [no run ID] error in stderr callback
Traceback (most recent call last):
  File "/usr/local/lib/python3.10/dist-packages/wandb/sdk/lib/redirect.py", line 662, in _on_write
    cb(written_data)
  File "/usr/local/lib/python3.10/dist-packages/wandb/sdk/wandb_run.py", line 2493, in <lambda>
    lambda data: self._console_raw_callback("stderr", data),
  File "/usr/local/lib/python3.10/dist-packages/wandb/sdk/wandb_run.py", line 406, in wrapper
    return func(self, *args, **kwargs)
  File "/usr/local/lib/python3.10/dist-packages/wandb/sdk/wandb_run.py", line 464, in wrapper_fn
    return func(self, *args, **kwargs)
  File "/usr/local/lib/python3.10/dist-packages/wandb/sdk/wandb_run.py", line 1632, in _console_raw_callback
    self._backend.interface.publish_output_raw(name, data)
  File "/usr/local/lib/python3.10/dist-packages/wandb/sdk/interface/interface.py", line 763, in publish_output_raw
    self._publish_output_raw(o)
  File "/usr/local/lib/python3.10/dist-packages/wandb/sdk/interface/interface_shared.py", line 38, in _publish_output_raw
    self._publish(rec)
  File "/usr/local/lib/python3.10/dist-packages/wandb/sdk/interface/interface_sock.py", line 39, in _publish
    self._sock_client.send_record_publish(record)
  File "/usr/local/lib/python3.10/dist-packages/wandb/sdk/lib/sock_client.py", line 174, in send_record_publish
    self.send_server_request(server_req)
  File "/usr/local/lib/python3.10/dist-packages/wandb/sdk/lib/sock_client.py", line 154, in send_server_request
    self._send_message(msg)
  File "/usr/local/lib/python3.10/dist-packages/wandb/sdk/lib/sock_client.py", line 151, in _send_message
    self._sendall_with_error_handle(header + data)
  File "/usr/local/lib/python3.10/dist-packages/wandb/sdk/lib/sock_client.py", line 130, in _sendall_with_error_handle
    sent = self._sock.send(data)
BrokenPipeError: [Errno 32] Broken pipe
2025-05-05 10:12:11,007 ERROR   MainThread:50994 [redirect.py:_on_write():664] [no run ID] error in stderr callback
Traceback (most recent call last):
  File "/usr/local/lib/python3.10/dist-packages/wandb/sdk/lib/redirect.py", line 662, in _on_write
    cb(written_data)
  File "/usr/local/lib/python3.10/dist-packages/wandb/sdk/wandb_run.py", line 2493, in <lambda>
    lambda data: self._console_raw_callback("stderr", data),
  File "/usr/local/lib/python3.10/dist-packages/wandb/sdk/wandb_run.py", line 406, in wrapper
    return func(self, *args, **kwargs)
  File "/usr/local/lib/python3.10/dist-packages/wandb/sdk/wandb_run.py", line 464, in wrapper_fn
    return func(self, *args, **kwargs)
  File "/usr/local/lib/python3.10/dist-packages/wandb/sdk/wandb_run.py", line 1632, in _console_raw_callback
    self._backend.interface.publish_output_raw(name, data)
  File "/usr/local/lib/python3.10/dist-packages/wandb/sdk/interface/interface.py", line 763, in publish_output_raw
    self._publish_output_raw(o)
  File "/usr/local/lib/python3.10/dist-packages/wandb/sdk/interface/interface_shared.py", line 38, in _publish_output_raw
    self._publish(rec)
  File "/usr/local/lib/python3.10/dist-packages/wandb/sdk/interface/interface_sock.py", line 39, in _publish
    self._sock_client.send_record_publish(record)
  File "/usr/local/lib/python3.10/dist-packages/wandb/sdk/lib/sock_client.py", line 174, in send_record_publish
    self.send_server_request(server_req)
  File "/usr/local/lib/python3.10/dist-packages/wandb/sdk/lib/sock_client.py", line 154, in send_server_request
    self._send_message(msg)
  File "/usr/local/lib/python3.10/dist-packages/wandb/sdk/lib/sock_client.py", line 151, in _send_message
    self._sendall_with_error_handle(header + data)
  File "/usr/local/lib/python3.10/dist-packages/wandb/sdk/lib/sock_client.py", line 130, in _sendall_with_error_handle
    sent = self._sock.send(data)
BrokenPipeError: [Errno 32] Broken pipe
2025-05-05 10:12:11,008 ERROR   MainThread:50994 [redirect.py:_on_write():664] [no run ID] error in stderr callback
Traceback (most recent call last):
  File "/usr/local/lib/python3.10/dist-packages/wandb/sdk/lib/redirect.py", line 662, in _on_write
    cb(written_data)
  File "/usr/local/lib/python3.10/dist-packages/wandb/sdk/wandb_run.py", line 2493, in <lambda>
    lambda data: self._console_raw_callback("stderr", data),
  File "/usr/local/lib/python3.10/dist-packages/wandb/sdk/wandb_run.py", line 406, in wrapper
    return func(self, *args, **kwargs)
  File "/usr/local/lib/python3.10/dist-packages/wandb/sdk/wandb_run.py", line 464, in wrapper_fn
    return func(self, *args, **kwargs)
  File "/usr/local/lib/python3.10/dist-packages/wandb/sdk/wandb_run.py", line 1632, in _console_raw_callback
    self._backend.interface.publish_output_raw(name, data)
  File "/usr/local/lib/python3.10/dist-packages/wandb/sdk/interface/interface.py", line 763, in publish_output_raw
    self._publish_output_raw(o)
  File "/usr/local/lib/python3.10/dist-packages/wandb/sdk/interface/interface_shared.py", line 38, in _publish_output_raw
    self._publish(rec)
  File "/usr/local/lib/python3.10/dist-packages/wandb/sdk/interface/interface_sock.py", line 39, in _publish
    self._sock_client.send_record_publish(record)
  File "/usr/local/lib/python3.10/dist-packages/wandb/sdk/lib/sock_client.py", line 174, in send_record_publish
    self.send_server_request(server_req)
  File "/usr/local/lib/python3.10/dist-packages/wandb/sdk/lib/sock_client.py", line 154, in send_server_request
    self._send_message(msg)
  File "/usr/local/lib/python3.10/dist-packages/wandb/sdk/lib/sock_client.py", line 151, in _send_message
    self._sendall_with_error_handle(header + data)
  File "/usr/local/lib/python3.10/dist-packages/wandb/sdk/lib/sock_client.py", line 130, in _sendall_with_error_handle
    sent = self._sock.send(data)
BrokenPipeError: [Errno 32] Broken pipe
2025-05-05 10:12:11,009 ERROR   MainThread:50994 [redirect.py:_on_write():664] [no run ID] error in stderr callback
Traceback (most recent call last):
  File "/usr/local/lib/python3.10/dist-packages/wandb/sdk/lib/redirect.py", line 662, in _on_write
    cb(written_data)
  File "/usr/local/lib/python3.10/dist-packages/wandb/sdk/wandb_run.py", line 2493, in <lambda>
    lambda data: self._console_raw_callback("stderr", data),
  File "/usr/local/lib/python3.10/dist-packages/wandb/sdk/wandb_run.py", line 406, in wrapper
    return func(self, *args, **kwargs)
  File "/usr/local/lib/python3.10/dist-packages/wandb/sdk/wandb_run.py", line 464, in wrapper_fn
    return func(self, *args, **kwargs)
  File "/usr/local/lib/python3.10/dist-packages/wandb/sdk/wandb_run.py", line 1632, in _console_raw_callback
    self._backend.interface.publish_output_raw(name, data)
  File "/usr/local/lib/python3.10/dist-packages/wandb/sdk/interface/interface.py", line 763, in publish_output_raw
    self._publish_output_raw(o)
  File "/usr/local/lib/python3.10/dist-packages/wandb/sdk/interface/interface_shared.py", line 38, in _publish_output_raw
    self._publish(rec)
  File "/usr/local/lib/python3.10/dist-packages/wandb/sdk/interface/interface_sock.py", line 39, in _publish
    self._sock_client.send_record_publish(record)
  File "/usr/local/lib/python3.10/dist-packages/wandb/sdk/lib/sock_client.py", line 174, in send_record_publish
    self.send_server_request(server_req)
  File "/usr/local/lib/python3.10/dist-packages/wandb/sdk/lib/sock_client.py", line 154, in send_server_request
    self._send_message(msg)
  File "/usr/local/lib/python3.10/dist-packages/wandb/sdk/lib/sock_client.py", line 151, in _send_message
    self._sendall_with_error_handle(header + data)
  File "/usr/local/lib/python3.10/dist-packages/wandb/sdk/lib/sock_client.py", line 130, in _sendall_with_error_handle
    sent = self._sock.send(data)
BrokenPipeError: [Errno 32] Broken pipe
2025-05-05 10:12:11,009 ERROR   MainThread:50994 [redirect.py:_on_write():664] [no run ID] error in stderr callback
Traceback (most recent call last):
  File "/usr/local/lib/python3.10/dist-packages/wandb/sdk/lib/redirect.py", line 662, in _on_write
    cb(written_data)
  File "/usr/local/lib/python3.10/dist-packages/wandb/sdk/wandb_run.py", line 2493, in <lambda>
    lambda data: self._console_raw_callback("stderr", data),
  File "/usr/local/lib/python3.10/dist-packages/wandb/sdk/wandb_run.py", line 406, in wrapper
    return func(self, *args, **kwargs)
  File "/usr/local/lib/python3.10/dist-packages/wandb/sdk/wandb_run.py", line 464, in wrapper_fn
    return func(self, *args, **kwargs)
  File "/usr/local/lib/python3.10/dist-packages/wandb/sdk/wandb_run.py", line 1632, in _console_raw_callback
    self._backend.interface.publish_output_raw(name, data)
  File "/usr/local/lib/python3.10/dist-packages/wandb/sdk/interface/interface.py", line 763, in publish_output_raw
    self._publish_output_raw(o)
  File "/usr/local/lib/python3.10/dist-packages/wandb/sdk/interface/interface_shared.py", line 38, in _publish_output_raw
    self._publish(rec)
  File "/usr/local/lib/python3.10/dist-packages/wandb/sdk/interface/interface_sock.py", line 39, in _publish
    self._sock_client.send_record_publish(record)
  File "/usr/local/lib/python3.10/dist-packages/wandb/sdk/lib/sock_client.py", line 174, in send_record_publish
    self.send_server_request(server_req)
  File "/usr/local/lib/python3.10/dist-packages/wandb/sdk/lib/sock_client.py", line 154, in send_server_request
    self._send_message(msg)
  File "/usr/local/lib/python3.10/dist-packages/wandb/sdk/lib/sock_client.py", line 151, in _send_message
    self._sendall_with_error_handle(header + data)
  File "/usr/local/lib/python3.10/dist-packages/wandb/sdk/lib/sock_client.py", line 130, in _sendall_with_error_handle
    sent = self._sock.send(data)
BrokenPipeError: [Errno 32] Broken pipe
2025-05-05 10:12:11,010 ERROR   MainThread:50994 [redirect.py:_on_write():664] [no run ID] error in stderr callback
Traceback (most recent call last):
  File "/usr/local/lib/python3.10/dist-packages/wandb/sdk/lib/redirect.py", line 662, in _on_write
    cb(written_data)
  File "/usr/local/lib/python3.10/dist-packages/wandb/sdk/wandb_run.py", line 2493, in <lambda>
    lambda data: self._console_raw_callback("stderr", data),
  File "/usr/local/lib/python3.10/dist-packages/wandb/sdk/wandb_run.py", line 406, in wrapper
    return func(self, *args, **kwargs)
  File "/usr/local/lib/python3.10/dist-packages/wandb/sdk/wandb_run.py", line 464, in wrapper_fn
    return func(self, *args, **kwargs)
  File "/usr/local/lib/python3.10/dist-packages/wandb/sdk/wandb_run.py", line 1632, in _console_raw_callback
    self._backend.interface.publish_output_raw(name, data)
  File "/usr/local/lib/python3.10/dist-packages/wandb/sdk/interface/interface.py", line 763, in publish_output_raw
    self._publish_output_raw(o)
  File "/usr/local/lib/python3.10/dist-packages/wandb/sdk/interface/interface_shared.py", line 38, in _publish_output_raw
    self._publish(rec)
  File "/usr/local/lib/python3.10/dist-packages/wandb/sdk/interface/interface_sock.py", line 39, in _publish
    self._sock_client.send_record_publish(record)
  File "/usr/local/lib/python3.10/dist-packages/wandb/sdk/lib/sock_client.py", line 174, in send_record_publish
    self.send_server_request(server_req)
  File "/usr/local/lib/python3.10/dist-packages/wandb/sdk/lib/sock_client.py", line 154, in send_server_request
    self._send_message(msg)
  File "/usr/local/lib/python3.10/dist-packages/wandb/sdk/lib/sock_client.py", line 151, in _send_message
    self._sendall_with_error_handle(header + data)
  File "/usr/local/lib/python3.10/dist-packages/wandb/sdk/lib/sock_client.py", line 130, in _sendall_with_error_handle
    sent = self._sock.send(data)
BrokenPipeError: [Errno 32] Broken pipe
2025-05-05 10:12:11,011 ERROR   MainThread:50994 [redirect.py:_on_write():664] [no run ID] error in stderr callback
Traceback (most recent call last):
  File "/usr/local/lib/python3.10/dist-packages/wandb/sdk/lib/redirect.py", line 662, in _on_write
    cb(written_data)
  File "/usr/local/lib/python3.10/dist-packages/wandb/sdk/wandb_run.py", line 2493, in <lambda>
    lambda data: self._console_raw_callback("stderr", data),
  File "/usr/local/lib/python3.10/dist-packages/wandb/sdk/wandb_run.py", line 406, in wrapper
    return func(self, *args, **kwargs)
  File "/usr/local/lib/python3.10/dist-packages/wandb/sdk/wandb_run.py", line 464, in wrapper_fn
    return func(self, *args, **kwargs)
  File "/usr/local/lib/python3.10/dist-packages/wandb/sdk/wandb_run.py", line 1632, in _console_raw_callback
    self._backend.interface.publish_output_raw(name, data)
  File "/usr/local/lib/python3.10/dist-packages/wandb/sdk/interface/interface.py", line 763, in publish_output_raw
    self._publish_output_raw(o)
  File "/usr/local/lib/python3.10/dist-packages/wandb/sdk/interface/interface_shared.py", line 38, in _publish_output_raw
    self._publish(rec)
  File "/usr/local/lib/python3.10/dist-packages/wandb/sdk/interface/interface_sock.py", line 39, in _publish
    self._sock_client.send_record_publish(record)
  File "/usr/local/lib/python3.10/dist-packages/wandb/sdk/lib/sock_client.py", line 174, in send_record_publish
    self.send_server_request(server_req)
  File "/usr/local/lib/python3.10/dist-packages/wandb/sdk/lib/sock_client.py", line 154, in send_server_request
    self._send_message(msg)
  File "/usr/local/lib/python3.10/dist-packages/wandb/sdk/lib/sock_client.py", line 151, in _send_message
    self._sendall_with_error_handle(header + data)
  File "/usr/local/lib/python3.10/dist-packages/wandb/sdk/lib/sock_client.py", line 130, in _sendall_with_error_handle
    sent = self._sock.send(data)
BrokenPipeError: [Errno 32] Broken pipe
2025-05-05 10:12:11,011 ERROR   MainThread:50994 [redirect.py:_on_write():664] [no run ID] error in stderr callback
Traceback (most recent call last):
  File "/usr/local/lib/python3.10/dist-packages/wandb/sdk/lib/redirect.py", line 662, in _on_write
    cb(written_data)
  File "/usr/local/lib/python3.10/dist-packages/wandb/sdk/wandb_run.py", line 2493, in <lambda>
    lambda data: self._console_raw_callback("stderr", data),
  File "/usr/local/lib/python3.10/dist-packages/wandb/sdk/wandb_run.py", line 406, in wrapper
    return func(self, *args, **kwargs)
  File "/usr/local/lib/python3.10/dist-packages/wandb/sdk/wandb_run.py", line 464, in wrapper_fn
    return func(self, *args, **kwargs)
  File "/usr/local/lib/python3.10/dist-packages/wandb/sdk/wandb_run.py", line 1632, in _console_raw_callback
    self._backend.interface.publish_output_raw(name, data)
  File "/usr/local/lib/python3.10/dist-packages/wandb/sdk/interface/interface.py", line 763, in publish_output_raw
    self._publish_output_raw(o)
  File "/usr/local/lib/python3.10/dist-packages/wandb/sdk/interface/interface_shared.py", line 38, in _publish_output_raw
    self._publish(rec)
  File "/usr/local/lib/python3.10/dist-packages/wandb/sdk/interface/interface_sock.py", line 39, in _publish
    self._sock_client.send_record_publish(record)
  File "/usr/local/lib/python3.10/dist-packages/wandb/sdk/lib/sock_client.py", line 174, in send_record_publish
    self.send_server_request(server_req)
  File "/usr/local/lib/python3.10/dist-packages/wandb/sdk/lib/sock_client.py", line 154, in send_server_request
    self._send_message(msg)
  File "/usr/local/lib/python3.10/dist-packages/wandb/sdk/lib/sock_client.py", line 151, in _send_message
    self._sendall_with_error_handle(header + data)
  File "/usr/local/lib/python3.10/dist-packages/wandb/sdk/lib/sock_client.py", line 130, in _sendall_with_error_handle
    sent = self._sock.send(data)
BrokenPipeError: [Errno 32] Broken pipe
2025-05-05 10:12:11,012 ERROR   MainThread:50994 [redirect.py:_on_write():664] [no run ID] error in stderr callback
Traceback (most recent call last):
  File "/usr/local/lib/python3.10/dist-packages/wandb/sdk/lib/redirect.py", line 662, in _on_write
    cb(written_data)
  File "/usr/local/lib/python3.10/dist-packages/wandb/sdk/wandb_run.py", line 2493, in <lambda>
    lambda data: self._console_raw_callback("stderr", data),
  File "/usr/local/lib/python3.10/dist-packages/wandb/sdk/wandb_run.py", line 406, in wrapper
    return func(self, *args, **kwargs)
  File "/usr/local/lib/python3.10/dist-packages/wandb/sdk/wandb_run.py", line 464, in wrapper_fn
    return func(self, *args, **kwargs)
  File "/usr/local/lib/python3.10/dist-packages/wandb/sdk/wandb_run.py", line 1632, in _console_raw_callback
    self._backend.interface.publish_output_raw(name, data)
  File "/usr/local/lib/python3.10/dist-packages/wandb/sdk/interface/interface.py", line 763, in publish_output_raw
    self._publish_output_raw(o)
  File "/usr/local/lib/python3.10/dist-packages/wandb/sdk/interface/interface_shared.py", line 38, in _publish_output_raw
    self._publish(rec)
  File "/usr/local/lib/python3.10/dist-packages/wandb/sdk/interface/interface_sock.py", line 39, in _publish
    self._sock_client.send_record_publish(record)
  File "/usr/local/lib/python3.10/dist-packages/wandb/sdk/lib/sock_client.py", line 174, in send_record_publish
    self.send_server_request(server_req)
  File "/usr/local/lib/python3.10/dist-packages/wandb/sdk/lib/sock_client.py", line 154, in send_server_request
    self._send_message(msg)
  File "/usr/local/lib/python3.10/dist-packages/wandb/sdk/lib/sock_client.py", line 151, in _send_message
    self._sendall_with_error_handle(header + data)
  File "/usr/local/lib/python3.10/dist-packages/wandb/sdk/lib/sock_client.py", line 130, in _sendall_with_error_handle
    sent = self._sock.send(data)
BrokenPipeError: [Errno 32] Broken pipe
2025-05-05 10:12:11,012 ERROR   MainThread:50994 [redirect.py:_on_write():664] [no run ID] error in stderr callback
Traceback (most recent call last):
  File "/usr/local/lib/python3.10/dist-packages/wandb/sdk/lib/redirect.py", line 662, in _on_write
    cb(written_data)
  File "/usr/local/lib/python3.10/dist-packages/wandb/sdk/wandb_run.py", line 2493, in <lambda>
    lambda data: self._console_raw_callback("stderr", data),
  File "/usr/local/lib/python3.10/dist-packages/wandb/sdk/wandb_run.py", line 406, in wrapper
    return func(self, *args, **kwargs)
  File "/usr/local/lib/python3.10/dist-packages/wandb/sdk/wandb_run.py", line 464, in wrapper_fn
    return func(self, *args, **kwargs)
  File "/usr/local/lib/python3.10/dist-packages/wandb/sdk/wandb_run.py", line 1632, in _console_raw_callback
    self._backend.interface.publish_output_raw(name, data)
  File "/usr/local/lib/python3.10/dist-packages/wandb/sdk/interface/interface.py", line 763, in publish_output_raw
    self._publish_output_raw(o)
  File "/usr/local/lib/python3.10/dist-packages/wandb/sdk/interface/interface_shared.py", line 38, in _publish_output_raw
    self._publish(rec)
  File "/usr/local/lib/python3.10/dist-packages/wandb/sdk/interface/interface_sock.py", line 39, in _publish
    self._sock_client.send_record_publish(record)
  File "/usr/local/lib/python3.10/dist-packages/wandb/sdk/lib/sock_client.py", line 174, in send_record_publish
    self.send_server_request(server_req)
  File "/usr/local/lib/python3.10/dist-packages/wandb/sdk/lib/sock_client.py", line 154, in send_server_request
    self._send_message(msg)
  File "/usr/local/lib/python3.10/dist-packages/wandb/sdk/lib/sock_client.py", line 151, in _send_message
    self._sendall_with_error_handle(header + data)
  File "/usr/local/lib/python3.10/dist-packages/wandb/sdk/lib/sock_client.py", line 130, in _sendall_with_error_handle
    sent = self._sock.send(data)
BrokenPipeError: [Errno 32] Broken pipe
2025-05-05 10:12:11,013 ERROR   MainThread:50994 [redirect.py:_on_write():664] [no run ID] error in stderr callback
Traceback (most recent call last):
  File "/usr/local/lib/python3.10/dist-packages/wandb/sdk/lib/redirect.py", line 662, in _on_write
    cb(written_data)
  File "/usr/local/lib/python3.10/dist-packages/wandb/sdk/wandb_run.py", line 2493, in <lambda>
    lambda data: self._console_raw_callback("stderr", data),
  File "/usr/local/lib/python3.10/dist-packages/wandb/sdk/wandb_run.py", line 406, in wrapper
    return func(self, *args, **kwargs)
  File "/usr/local/lib/python3.10/dist-packages/wandb/sdk/wandb_run.py", line 464, in wrapper_fn
    return func(self, *args, **kwargs)
  File "/usr/local/lib/python3.10/dist-packages/wandb/sdk/wandb_run.py", line 1632, in _console_raw_callback
    self._backend.interface.publish_output_raw(name, data)
  File "/usr/local/lib/python3.10/dist-packages/wandb/sdk/interface/interface.py", line 763, in publish_output_raw
    self._publish_output_raw(o)
  File "/usr/local/lib/python3.10/dist-packages/wandb/sdk/interface/interface_shared.py", line 38, in _publish_output_raw
    self._publish(rec)
  File "/usr/local/lib/python3.10/dist-packages/wandb/sdk/interface/interface_sock.py", line 39, in _publish
    self._sock_client.send_record_publish(record)
  File "/usr/local/lib/python3.10/dist-packages/wandb/sdk/lib/sock_client.py", line 174, in send_record_publish
    self.send_server_request(server_req)
  File "/usr/local/lib/python3.10/dist-packages/wandb/sdk/lib/sock_client.py", line 154, in send_server_request
    self._send_message(msg)
  File "/usr/local/lib/python3.10/dist-packages/wandb/sdk/lib/sock_client.py", line 151, in _send_message
    self._sendall_with_error_handle(header + data)
  File "/usr/local/lib/python3.10/dist-packages/wandb/sdk/lib/sock_client.py", line 130, in _sendall_with_error_handle
    sent = self._sock.send(data)
BrokenPipeError: [Errno 32] Broken pipe
2025-05-05 10:12:11,014 ERROR   MainThread:50994 [redirect.py:_on_write():664] [no run ID] error in stderr callback
Traceback (most recent call last):
  File "/usr/local/lib/python3.10/dist-packages/wandb/sdk/lib/redirect.py", line 662, in _on_write
    cb(written_data)
  File "/usr/local/lib/python3.10/dist-packages/wandb/sdk/wandb_run.py", line 2493, in <lambda>
    lambda data: self._console_raw_callback("stderr", data),
  File "/usr/local/lib/python3.10/dist-packages/wandb/sdk/wandb_run.py", line 406, in wrapper
    return func(self, *args, **kwargs)
  File "/usr/local/lib/python3.10/dist-packages/wandb/sdk/wandb_run.py", line 464, in wrapper_fn
    return func(self, *args, **kwargs)
  File "/usr/local/lib/python3.10/dist-packages/wandb/sdk/wandb_run.py", line 1632, in _console_raw_callback
    self._backend.interface.publish_output_raw(name, data)
  File "/usr/local/lib/python3.10/dist-packages/wandb/sdk/interface/interface.py", line 763, in publish_output_raw
    self._publish_output_raw(o)
  File "/usr/local/lib/python3.10/dist-packages/wandb/sdk/interface/interface_shared.py", line 38, in _publish_output_raw
    self._publish(rec)
  File "/usr/local/lib/python3.10/dist-packages/wandb/sdk/interface/interface_sock.py", line 39, in _publish
    self._sock_client.send_record_publish(record)
  File "/usr/local/lib/python3.10/dist-packages/wandb/sdk/lib/sock_client.py", line 174, in send_record_publish
    self.send_server_request(server_req)
  File "/usr/local/lib/python3.10/dist-packages/wandb/sdk/lib/sock_client.py", line 154, in send_server_request
    self._send_message(msg)
  File "/usr/local/lib/python3.10/dist-packages/wandb/sdk/lib/sock_client.py", line 151, in _send_message
    self._sendall_with_error_handle(header + data)
  File "/usr/local/lib/python3.10/dist-packages/wandb/sdk/lib/sock_client.py", line 130, in _sendall_with_error_handle
    sent = self._sock.send(data)
BrokenPipeError: [Errno 32] Broken pipe
